<?xml version="1.0"?>
<!-- Revolute-Revolute Manipulator -->
<robot name="rx90" xmlns:xacro="http://www.ros.org/wiki/xacro">

  <!-- Constants for robot dimensions -->


  <!-- Import all Gazebo-customization elements, including Gazebo colors -->
  <xacro:include filename="$(find rx90_description)/urdf/rx90.gazebo" />
  <!-- Import Rviz colors -->
  <xacro:include filename="$(find rx90_description)/urdf/materials.xacro" />
  
    


  <link name="world"/>
<!--link name="base_link"/-->
<!--BRAZOOOOOOOOOOOOOOOOOOOO-->


<!-- Joint 0 -->
  

    <link name="RX90_BASE">
       <visual>
	<origin rpy="${pi/2} 0 0" xyz="0 0 0" />
          <geometry>
             <mesh filename="package://rx90_description/meshes/stl/RX-90_BASE.stl" scale="0.001 0.001 0.001" />
          </geometry>
       </visual>
	<collision>
        <origin rpy="${pi/2} 0 0" xyz="0 0 0" />
            <geometry>
              <mesh filename="package://rx90_description/meshes/stl/RX-90_BASE.stl" scale="0.001 0.001 0.001" />
            </geometry>
       </collision>
       <selfCollide>true</selfCollide>
	<inertial>
       <mass value="1"/>
          <origin xyz="0.0 0.00 0.0" rpy="0.0 0.0 0.0"/>
          <inertia ixx="1"  ixy="1"  ixz="1"
                   iyx="1"  iyy="1"  iyz="1"
                   izx="1"  izy="1"  izz="1"/>
    </inertial>
    </link>
    <joint name="RX90_BASE_JOINT" type="fixed">
       <parent link="world" />
       <child link="RX90_BASE" />
       <origin rpy="0 0 0" xyz="0 0 0.083" />
    </joint>

    <link name="RX90_SHOULDER">
       <visual>
	<origin rpy="0 ${-pi/2} ${pi/2}" xyz="0.122 0 0" />
          <geometry>
             <mesh filename="package://rx90_description/meshes/stl/RX-90_SHOULDER.stl" scale="0.001 0.001 0.001" />
          </geometry>
       </visual>
	<collision>
        <origin rpy="0 ${-pi/2} ${pi/2}" xyz="0.122 0 0" />
            <geometry>
              <mesh filename="package://rx90_description/meshes/stl/RX-90_SHOULDER.stl" scale="0.001 0.001 0.001" />
            </geometry>
       </collision>
       <selfCollide>true</selfCollide>
	<inertial>
      <mass value="1"/>
      <origin xyz="0.0 0.00 0.0" rpy="0.0 0.0 0.0"/>
          <inertia ixx="1"  ixy="1"  ixz="1"
                   iyx="1"  iyy="1"  iyz="1"
                   izx="1"  izy="1"  izz="1"/>
    </inertial>
    </link>
    <joint name="RX90_SHOULDER_JOINT" type="revolute">
    <limit effort="10000" lower="-2.7925" upper="2.7925" velocity="4.1189"/>
       <parent link="RX90_BASE" />
       <child link="RX90_SHOULDER" />
       <origin rpy="0 ${pi/2} 0" xyz="0 0 0.41" />
    </joint>

<link name="RX90_ARM">
       <visual>
	<origin rpy="0 0 ${pi/2}" xyz="0 0 0" />
          <geometry>
             <mesh filename="package://rx90_description/meshes/stl/RX-90_ARM.stl" scale="0.001 0.001 0.001" />
          </geometry>
       </visual>
	<collision>
        <origin rpy="0 0 ${pi/2}" xyz="0 0 0" />
            <geometry>
              <mesh filename="package://rx90_description/meshes/stl/RX-90_ARM.stl" scale="0.001 0.001 0.001" />
            </geometry>
       </collision>
       <selfCollide>true</selfCollide>
	<inertial>
        <mass value="1"/>
  <origin xyz="0.0 0.00 0.0" rpy="0.0 0.0 0.0"/>
          <inertia ixx="1"  ixy="1"  ixz="1"
                   iyx="1"  iyy="1"  iyz="1"
                   izx="1"  izy="1"  izz="1"/>
    </inertial>
    </link>
    <joint name="RX90_ARM_JOINT" type="revolute">
    <limit effort="10000" lower="-2.39" upper="2.39" velocity="3.4906"/>
       <parent link="RX90_SHOULDER" />
       <child link="RX90_ARM" />
       <origin rpy="0 ${pi/2} 0" xyz="0 0 -0.301" />
    </joint>

    <link name="RX90_ELBOW">
       <visual>
	<origin rpy="${-pi/2} ${-pi/2} ${-pi/2}" xyz="-0.021 0.14 0" />
          <geometry>
             <mesh filename="package://rx90_description/meshes/stl/RX-90_ELBOW.stl" scale="0.001 0.001 0.001" />
          </geometry>
       </visual>
	<collision>
        <origin rpy="${-pi/2} ${-pi/2} ${-pi/2}" xyz="-0.021 0.14 0" />
            <geometry>
              <mesh filename="package://rx90_description/meshes/stl/RX-90_ELBOW.stl" scale="0.001 0.001 0.001" />
            </geometry>
       </collision>
       <selfCollide>true</selfCollide>
	<inertial>
  <mass value="1"/>
        <origin xyz="0.0 0.00 0.0" rpy="0.0 0.0 0.0"/>
          <inertia ixx="1"  ixy="1"  ixz="1"
                   iyx="1"  iyy="1"  iyz="1"
                   izx="1"  izy="1"  izz="1"/>
    </inertial>
    </link>
    <joint name="RX90_ELBOW_JOINT" type="revolute">
    <limit effort="10000" lower="-2.487" upper="2.487" velocity="4.9916"/>
       <parent link="RX90_ARM" />
       <child link="RX90_ELBOW" />
       <origin rpy="${pi/2} 0 0" xyz="-0.255 0 -0.46" />
    </joint>


  <link name="RX90_FOREARM">
       <visual>
	<origin rpy="${pi} ${-pi/2} 0" xyz="0.355 0.1 -0.05" />
          <geometry>
             <mesh filename="package://rx90_description/meshes/stl/RX-90_FOREARM.stl" scale="0.001 0.001 0.001" />
          </geometry>
       </visual>
	<collision>
        <origin rpy="${pi} ${-pi/2} 0" xyz="0.355 0.1 -0.05" />
            <geometry>
              <mesh filename="package://rx90_description/meshes/stl/RX-90_FOREARM.stl" scale="0.001 0.001 0.001" />
            </geometry>
       </collision>
       <selfCollide>true</selfCollide>
	<inertial>
        <mass value="1"/>
          <origin xyz="0.0 0.00 0.0" rpy="0.0 0.0 0.0"/>
          <inertia ixx="1"  ixy="1"  ixz="1"
                   iyx="1"  iyy="1"  iyz="1"
                   izx="1"  izy="1"  izz="1"/>
    </inertial>
    </link>
    <joint name="RX90_FOREARM_JOINT" type="revolute">
    <limit effort="10000" lower="-4.712" upper="4.712" velocity="6.9987"/>
       <parent link="RX90_ELBOW" />
       <child link="RX90_FOREARM" />
       <origin rpy="0 0 ${-pi/2}" xyz="0 0 0" />
    </joint>

      <link name="RX90_WRIST">
       <visual>
	<origin rpy="${pi/2} 0 ${-pi/2}" xyz="-0.007 0 -0.01" />
          <geometry>
             <mesh filename="package://rx90_description/meshes/stl/RX-90_WRIST.stl" scale="0.001 0.001 0.001" />
          </geometry>
       </visual>
	<collision>
        <origin rpy="${pi/2} 0 ${-pi/2}" xyz="-0.007 0 -0.01" />
            <geometry>
              <mesh filename="package://rx90_description/meshes/stl/RX-90_WRIST.stl" scale="0.001 0.001 0.001" />
            </geometry>
       </collision>
       <selfCollide>true</selfCollide>
	<inertial>
       <mass value="1"/>
         <origin xyz="0.0 0.00 0.0" rpy="0.0 0.0 0.0"/>
          <inertia ixx="1"  ixy="1"  ixz="1"
                   iyx="1"  iyy="1"  iyz="1"
                   izx="1"  izy="1"  izz="1"/>
    </inertial>
    </link>
    <joint name="RX90_WRIST_JOINT" type="revolute">
    <limit effort="10000" lower="-2" upper="1.8325" velocity="5.585"/>
       <parent link="RX90_FOREARM" />
       <child link="RX90_WRIST" />
       <origin rpy="0 0 ${pi/2}" xyz="0.52 0 0" />
    </joint>

          <link name="RX90_FLANGE">
       <visual>
	<origin rpy="0 ${pi/2} 0" xyz="0 0 0" />
          <geometry>
             <mesh filename="package://rx90_description/meshes/stl/RX-90_FLANGE.stl" scale="0.001 0.001 0.001" />
          </geometry>
       </visual>
	<collision>
        <origin rpy="0 ${pi/2} 0" xyz="0 0 -0.009" />
            <geometry>
              <mesh filename="package://rx90_description/meshes/stl/RX-90_FLANGE.stl" scale="0.001 0.001 0.001" />
            </geometry>
       </collision>
       <selfCollide>true</selfCollide>
	<inertial>
         <origin xyz="0 0 0" rpy="0 0 0" />
         <mass value="1"/>
        <origin xyz="0.0 0.00 0.0" rpy="0.0 0.0 0.0"/>
          <inertia ixx="1"  ixy="1"  ixz="1"
                   iyx="1"  iyy="1"  iyz="1"
                   izx="1"  izy="1"  izz="1"/>
    </inertial>
    </link>
    <joint name="RX90_FLANGE_JOINT" type="revolute">
    <limit effort="10000" lower="-4.712" upper="4.712" velocity="10.122"/>
       <parent link="RX90_WRIST" />
       <child link="RX90_FLANGE" />
       <origin rpy="0 0 ${-pi/2}" xyz="-0.006 -0.1015 -0.009" />
    </joint>


          <link name="RX90_LGRIPPER">
       <visual>
	<origin rpy="0 0 0" xyz="0 0 0" />
          <geometry>
            <box size="0.02 0.045 0.01"/>
          </geometry>
       </visual>
	<collision>
        <origin rpy="0 0 0" xyz="0 0 0" />
            <geometry>
              <box size="0.02 0.045 0.01"/>
            </geometry>
       </collision>
       <selfCollide>true</selfCollide>
	<inertial>
       
        <mass value="1" />
  <origin xyz="0.0 0.00 0.0" rpy="0.0 0.0 0.0"/>
          <inertia ixx="1"  ixy="1"  ixz="1"
                   iyx="1"  iyy="1"  iyz="1"
                   izx="1"  izy="1"  izz="1"/>
    </inertial>
    </link>
    <joint name="RX90_LGRIPPER_JOINT" type="prismatic">
    <limit effort="100000.0" lower="-0.01" upper="0.08" velocity="20"/>
       <parent link="RX90_FLANGE" />
       <child link="RX90_LGRIPPER" />
       <origin rpy="0 0 ${-pi/2}" xyz="0.025 0.03 0.015" />
    </joint>

 <link name="RX90_RGRIPPER">
       <visual>
	<origin rpy="0 0 0" xyz="0 0 0" />
          <geometry>
            <box size="0.02 0.045 0.01"/>
          </geometry>
       </visual>
	<collision>
        <origin rpy="0 0 0" xyz="0 0 0" />
            <geometry>
              <box size="0.02 0.045 0.01"/>
            </geometry>
       </collision>
       <selfCollide>true</selfCollide>
	<inertial>
       <origin xyz="0 0 0" rpy="0 0 0" />
        <mass value="1" />
  
          <inertia ixx="1"  ixy="1"  ixz="1"
                   iyx="1"  iyy="1"  iyz="1"
                   izx="1"  izy="1"  izz="1"/>
    
    </inertial>
    </link>
    <joint name="RX90_RGRIPPER_JOINT" type="prismatic">
    <limit effort="100000.0" lower="-0.08" upper="0.01" velocity="20"/>
       <parent link="RX90_FLANGE" />
       <child link="RX90_RGRIPPER" />
       <origin rpy="0 0 ${-pi/2}" xyz="0.025 -0.03 0.015" />
    </joint>


     <link name="RX90_MGRIPPER">
       <visual>
	<origin rpy="0 0 0" xyz="0 0 0" />
          <geometry>
            <box size="0.02 0.045 0.01"/>
          </geometry>
       </visual>
	<collision>
        <origin rpy="0 0 0" xyz="0 0 0" />
            <geometry>
              <box size="0.02 0.045 0.01"/>
            </geometry>
       </collision>
       <selfCollide>true</selfCollide>
	<inertial>
       <origin xyz="0 0 0" rpy="0 0 0" />
        <mass value="1" />
   
          <inertia ixx="1"  ixy="1"  ixz="1"
                   iyx="1"  iyy="1"  iyz="1"
                   izx="1"  izy="1"  izz="1"/>
    
    </inertial>
    </link>
    <joint name="RX90_MGRIPPER_JOINT" type="prismatic">
    <limit effort="100000.0" lower="-0.08" upper="0.01" velocity="20"/>
       <parent link="RX90_FLANGE" />
       <child link="RX90_MGRIPPER" />
       <origin rpy="0 ${pi/2} ${-pi/2}" xyz="0.025 0 -0.035" />
    </joint>
 


<!--BRAZOOOOOOOOOOOOOOOOOOOOooooooooooooooooooooooooooooooooooooooo-->

  <!-- Base Link -->

  
<!--TRANSMISION BRAZO-->


<transmission name="tran_RX90_SHOULDER_JOINT">
    <type>transmission_interface/SimpleTransmission</type>
    <joint name="RX90_SHOULDER_JOINT">
      <hardwareInterface>hardware_interface/EffortJointInterface</hardwareInterface>
    </joint>
    <actuator name="motor_RX90_SHOULDER_JOINT">
      <hardwareInterface>hardware_interface/EffortJointInterface</hardwareInterface>
      <mechanicalReduction>1</mechanicalReduction>
    </actuator>
  </transmission>

<transmission name="tran_RX90_ARM_JOINT">
    <type>transmission_interface/SimpleTransmission</type>
    <joint name="RX90_ARM_JOINT">
      <hardwareInterface>hardware_interface/EffortJointInterface</hardwareInterface>
    </joint>
    <actuator name="motor_RX90_ARM_JOINT">
      <hardwareInterface>hardware_interface/EffortJointInterface</hardwareInterface>
      <mechanicalReduction>1</mechanicalReduction>
    </actuator>
  </transmission>

  <transmission name="tran_RX90_ELBOW_JOINT">
    <type>transmission_interface/SimpleTransmission</type>
    <joint name="RX90_ELBOW_JOINT">
      <hardwareInterface>hardware_interface/EffortJointInterface</hardwareInterface>
    </joint>
    <actuator name="motor_RX90_ELBOW_JOINT">
      <hardwareInterface>hardware_interface/EffortJointInterface</hardwareInterface>
      <mechanicalReduction>1</mechanicalReduction>
    </actuator>
  </transmission>

  <transmission name="tran_RX90_FOREARM_JOINT">
    <type>transmission_interface/SimpleTransmission</type>
    <joint name="RX90_FOREARM_JOINT">
      <hardwareInterface>hardware_interface/EffortJointInterface</hardwareInterface>
    </joint>
    <actuator name="motor_RX90_FOREARM_JOINT">
      <hardwareInterface>hardware_interface/EffortJointInterface</hardwareInterface>
      <mechanicalReduction>1</mechanicalReduction>
    </actuator>
  </transmission>

  <transmission name="tran_RX90_WRIST_JOINT">
    <type>transmission_interface/SimpleTransmission</type>
    <joint name="RX90_WRIST_JOINT">
      <hardwareInterface>hardware_interface/EffortJointInterface</hardwareInterface>
    </joint>
    <actuator name="motor_RX90_WRIST_JOINT">
      <hardwareInterface>hardware_interface/EffortJointInterface</hardwareInterface>
      <mechanicalReduction>1</mechanicalReduction>
    </actuator>
  </transmission>

  <transmission name="tran_RX90_FLANGE_JOINT">
    <type>transmission_interface/SimpleTransmission</type>
    <joint name="RX90_FLANGE_JOINT">
      <hardwareInterface>hardware_interface/EffortJointInterface</hardwareInterface>
    </joint>
    <actuator name="motor_RX90_FLANGE_JOINT">
      <hardwareInterface>hardware_interface/EffortJointInterface</hardwareInterface>
      <mechanicalReduction>1</mechanicalReduction>
    </actuator>
  </transmission>

    <transmission name="tran_RX90_LGRIPPER_JOINT">
    <type>transmission_interface/SimpleTransmission</type>
    <joint name="RX90_LGRIPPER_JOINT">
      <hardwareInterface>hardware_interface/EffortJointInterface</hardwareInterface>
    </joint>
    <actuator name="motor_RX90_LGRIPPER_JOINT">
      <hardwareInterface>hardware_interface/EffortJointInterface</hardwareInterface>
      <mechanicalReduction>1</mechanicalReduction>
    </actuator>
  </transmission>

    <transmission name="tran_RX90_RGRIPPER_JOINT">
    <type>transmission_interface/SimpleTransmission</type>
    <joint name="RX90_RGRIPPER_JOINT">
      <hardwareInterface>hardware_interface/EffortJointInterface</hardwareInterface>
    </joint>
    <actuator name="motor_RX90_RGRIPPER_JOINT">
      <hardwareInterface>hardware_interface/EffortJointInterface</hardwareInterface>
      <mechanicalReduction>1</mechanicalReduction>
    </actuator>
  </transmission>

      <transmission name="tran_RX90_MGRIPPER_JOINT">
    <type>transmission_interface/SimpleTransmission</type>
    <joint name="RX90_MGRIPPER_JOINT">
      <hardwareInterface>hardware_interface/EffortJointInterface</hardwareInterface>
    </joint>
    <actuator name="motor_RX90_MGRIPPER_JOINT">
      <hardwareInterface>hardware_interface/EffortJointInterface</hardwareInterface>
      <mechanicalReduction>1</mechanicalReduction>
    </actuator>
  </transmission>



</robot>
