<?xml version="1.0" encoding="UTF-8"?>
<robot name="RX90">
   <!-- BASE -->
   <link name="base_link">
      <visual>
         <origin rpy="0 0 0" xyz="0 0 0" />
      </visual>
   </link>


   <link name="RX90_BARREL">
      <visual>
         <geometry>
            <mesh filename="package://rx90_description/meshes/stl/RX-90_BARREL.stl" scale="0.001 0.001 0.001" />
         </geometry>
          <origin rpy="${pi/2} 0 0" xyz="0 0 0" />
      </visual>
      <collision>
        <origin rpy="${pi/2} 0 0" xyz="0 0 0" />
            <geometry>
              <mesh filename="package://rx90_description/meshes/stl/RX-90_BARREL.stl" scale="0.001 0.001 0.001" />
            </geometry>
       </collision>
       <selfCollide>true</selfCollide>
	<inertial>
        <origin xyz="0 0 0" rpy="0 0 0" />
        <mass value="1" />
        <inertia
          ixx="1.0" ixy="0.0" ixz="0.0"
          iyy="1.0" iyz="0.0"
          izz="1.0" />
    </inertial>
   </link>
   <joint name="RX90_BARREL_JOINT" type="fixed">
      <parent link="base_link" />
      <child link="RX90_BARREL" />
      <origin rpy="0 0 0" xyz="0 0 0" />
   </joint>

    <link name="RX90_BASE">
       <visual>
	<origin rpy="${pi/2} 0 0" xyz="0 0 0" />
          <geometry>
             <mesh filename="package://rx90_description/meshes/stl/RX-90_BASE.stl" scale="0.001 0.001 0.001" />
          </geometry>
       </visual>
	<collision>
        <origin rpy="${pi/2} 0 0" xyz="0 0 0" />
            <geometry>
              <mesh filename="package://rx90_description/meshes/stl/RX-90_BASE.stl" scale="0.001 0.001 0.001" />
            </geometry>
       </collision>
       <selfCollide>true</selfCollide>
	<inertial>
       <mass value="23.085357"/>
          <origin xyz="0.007579 0.000017 0.180670" rpy="0.0 0.0 0.0"/>
          <inertia ixx="0.343576" ixy="-0.000062" ixz="-0.002079"
                                  iyy="0.336217"  iyz="-0.000014"
                                                  izz="0.334050"/>
    </inertial>
    </link>
    <joint name="RX90_BASE_JOINT" type="fixed">
       <parent link="RX90_BARREL" />
       <child link="RX90_BASE" />
       <origin rpy="0 0 0" xyz="0 0 1.005" />
    </joint>

    <link name="RX90_SHOULDER">
       <visual>
	<origin rpy="0 ${-pi/2} ${pi/2}" xyz="0.122 0 0" />
          <geometry>
             <mesh filename="package://rx90_description/meshes/stl/RX-90_SHOULDER.stl" scale="0.001 0.001 0.001" />
          </geometry>
       </visual>
	<collision>
        <origin rpy="0 ${-pi/2} ${pi/2}" xyz="0.122 0 0" />
            <geometry>
              <mesh filename="package://rx90_description/meshes/stl/RX-90_SHOULDER.stl" scale="0.001 0.001 0.001" />
            </geometry>
       </collision>
       <selfCollide>true</selfCollide>
	<inertial>
      <mass value="45.357763"/>
          <origin xyz="0.085479 -0.002547 -0.040488" rpy="0.0 0.0 0.0"/>
          <inertia ixx="0.839141" ixy="0.022637" ixz="0.162457"
                                  iyy="1.030146" iyz="0.027416"
                                                  izz="1.064698"/>
    </inertial>
    </link>
    <joint name="RX90_SHOULDER_JOINT" type="revolute">
    <limit effort="10000" lower="-2.7925" upper="2.7925" velocity="4.1189"/>
       <parent link="RX90_BASE" />
       <child link="RX90_SHOULDER" />
       <origin rpy="0 ${pi/2} 0" xyz="0 0 0.41" />
    </joint>

<link name="RX90_ARM">
       <visual>
	<origin rpy="0 0 ${pi/2}" xyz="0 0 0" />
          <geometry>
             <mesh filename="package://rx90_description/meshes/stl/RX-90_ARM.stl" scale="0.001 0.001 0.001" />
          </geometry>
       </visual>
	<collision>
        <origin rpy="0 0 ${pi/2}" xyz="0 0 0" />
            <geometry>
              <mesh filename="package://rx90_description/meshes/stl/RX-90_ARM.stl" scale="0.001 0.001 0.001" />
            </geometry>
       </collision>
       <selfCollide>true</selfCollide>
	<inertial>
        <mass value="51.266495"/>
          <origin xyz="-0.000002 0.264164 0.347704" rpy="0.0 0.0 0.0"/>
          <inertia ixx="5.272800" ixy="0.000010" ixz="0.000017"
                                  iyy="5.536809" iyz="-0.008261"
                                                  izz="0.486191"/>
    </inertial>
    </link>
    <joint name="RX90_ARM_JOINT" type="revolute">
    <limit effort="10000" lower="-0.82" upper="3.96" velocity="3.4906"/>
       <parent link="RX90_SHOULDER" />
       <child link="RX90_ARM" />
       <origin rpy="0 ${pi/2} ${pi/2}" xyz="0 0 -0.301" />
    </joint>

    <link name="RX90_ELBOW">
       <visual>
	<origin rpy="${-pi/2} ${-pi/2} ${-pi/2}" xyz="-0.021 0.14 0" />
          <geometry>
             <mesh filename="package://rx90_description/meshes/stl/RX-90_ELBOW.stl" scale="0.001 0.001 0.001" />
          </geometry>
       </visual>
	<collision>
        <origin rpy="${-pi/2} ${-pi/2} ${-pi/2}" xyz="-0.021 0.14 0" />
            <geometry>
              <mesh filename="package://rx90_description/meshes/stl/RX-90_ELBOW.stl" scale="0.001 0.001 0.001" />
            </geometry>
       </collision>
       <selfCollide>true</selfCollide>
	<inertial>
  <mass value="19.754401"/>
          <origin xyz="-0.000255 0.016478 -0.003819" rpy="0.0 0.0 0.0"/>
          <inertia ixx="0.249388" ixy="-0.004901" ixz="0.004825"
                                  iyy="0.211780"  iyz="0.000574"
                                                  izz="0.238488"/>
    </inertial>
    </link>
    <joint name="RX90_ELBOW_JOINT" type="revolute">
    <limit effort="10000" lower="-0.917" upper="4.057" velocity="4.9916"/>
       <parent link="RX90_ARM" />
       <child link="RX90_ELBOW" />
       <origin rpy="0 0 0" xyz="-0.255 0 -0.46" />
    </joint>


  <link name="RX90_FOREARM">
       <visual>
	<origin rpy="${pi} ${-pi/2} 0" xyz="0.355 0.1 -0.05" />
          <geometry>
             <mesh filename="package://rx90_description/meshes/stl/RX-90_FOREARM.stl" scale="0.001 0.001 0.001" />
          </geometry>
       </visual>
	<collision>
        <origin rpy="${pi} ${-pi/2} 0" xyz="0.355 0.1 -0.05" />
            <geometry>
              <mesh filename="package://rx90_description/meshes/stl/RX-90_FOREARM.stl" scale="0.001 0.001 0.001" />
            </geometry>
       </collision>
       <selfCollide>true</selfCollide>
	<inertial>
        <mass value="15.287896"/>
          <origin xyz="-0.015515 0.000164 0.340348" rpy="0.0 0.0 0.0"/>
          <inertia ixx="0.331593" ixy="0.000055" ixz="-0.010688"
                                  iyy="0.320895" iyz="0.000058"
                                                  izz="0.086557"/>
    </inertial>
    </link>
    <joint name="RX90_FOREARM_JOINT" type="revolute">
    <limit effort="10000" lower="-4.712" upper="4.712" velocity="6.9987"/>
       <parent link="RX90_ELBOW" />
       <child link="RX90_FOREARM" />
       <origin rpy="0 0 ${-pi/2}" xyz="0 0 0" />
    </joint>

      <link name="RX90_WRIST">
       <visual>
	<origin rpy="${pi/2} 0 ${-pi/2}" xyz="-0.007 0 -0.01" />
          <geometry>
             <mesh filename="package://rx90_description/meshes/stl/RX-90_WRIST.stl" scale="0.001 0.001 0.001" />
          </geometry>
       </visual>
	<collision>
        <origin rpy="${pi/2} 0 ${-pi/2}" xyz="-0.007 0 -0.01" />
            <geometry>
              <mesh filename="package://rx90_description/meshes/stl/RX-90_WRIST.stl" scale="0.001 0.001 0.001" />
            </geometry>
       </collision>
       <selfCollide>true</selfCollide>
	<inertial>
       <mass value="0.548088"/>
          <origin xyz="0.000000 -0.000347 0.023671" rpy="0.0 0.0 0.0"/>
          <inertia ixx="0.000876" ixy="0.000000" ixz="0.000000"
                                  iyy="0.000889" iyz="0.000005"
                                                  izz="0.000412"/>
    </inertial>
    </link>
    <joint name="RX90_WRIST_JOINT" type="revolute">
    <limit effort="10000" lower="-2" upper="1.8325" velocity="5.585"/>
       <parent link="RX90_FOREARM" />
       <child link="RX90_WRIST" />
       <origin rpy="0 0 ${pi/2}" xyz="0.52 0 0" />
    </joint>

          <link name="RX90_FLANGE">
       <visual>
	<origin rpy="0 ${pi/2} 0" xyz="0 0 0" />
          <geometry>
             <mesh filename="package://rx90_description/meshes/stl/RX-90_FLANGE.stl" scale="0.001 0.001 0.001" />
          </geometry>
       </visual>
	<collision>
        <origin rpy="0 ${pi/2} 0" xyz="0 0 -0.009" />
            <geometry>
              <mesh filename="package://rx90_description/meshes/stl/RX-90_FLANGE.stl" scale="0.001 0.001 0.001" />
            </geometry>
       </collision>
       <selfCollide>true</selfCollide>
	<inertial>
         <origin xyz="0 0 0" rpy="0 0 0" />
         <mass value="0.038484"/>
          <origin xyz="-0.000245 0.000000 -0.007626" rpy="0.0 0.0 0.0"/>
          <inertia ixx="0" ixy="0.000000" ixz="0.000000"
                                  iyy="0.0000" iyz="0.000000"
                                                  izz="0.0000"/>
    </inertial>
    </link>
    <joint name="RX90_FLANGE_JOINT" type="revolute">
    <limit effort="10000" lower="-4.712" upper="4.712" velocity="10.122"/>
       <parent link="RX90_WRIST" />
       <child link="RX90_FLANGE" />
       <origin rpy="0 0 ${-pi/2}" xyz="-0.006 -0.1015 -0.009" />
    </joint>


          <link name="RX90_LGRIPPER">
       <visual>
	<origin rpy="0 0 0" xyz="0 0 0" />
          <geometry>
            <box size="0.02 0.045 0.01"/>
          </geometry>
       </visual>
	<collision>
        <origin rpy="0 0 0" xyz="0 0 0" />
            <geometry>
              <box size="0.02 0.045 0.01"/>
            </geometry>
       </collision>
       <selfCollide>true</selfCollide>
	<inertial>
        <origin xyz="0 0 0" rpy="0 0 0" />
        <mass value="0.038484" />
        <inertia
          ixx="0.0" ixy="0.0" ixz="0.0"
          iyy="0.0" iyz="0.0"
          izz="0.0" />
    </inertial>
    </link>
    <joint name="RX90_LGRIPPER_JOINT" type="prismatic">
    <limit effort="100000.0" lower="-100000" upper="1" velocity="20"/>
       <parent link="RX90_FLANGE" />
       <child link="RX90_LGRIPPER" />
       <origin rpy="0 0 ${-pi/2}" xyz="0.025 0.03 0.015" />
    </joint>

 <link name="RX90_RGRIPPER">
       <visual>
	<origin rpy="0 0 0" xyz="0 0 0" />
          <geometry>
            <box size="0.02 0.045 0.01"/>
          </geometry>
       </visual>
	<collision>
        <origin rpy="0 0 0" xyz="0 0 0" />
            <geometry>
              <box size="0.02 0.045 0.01"/>
            </geometry>
       </collision>
       <selfCollide>true</selfCollide>
	<inertial>
       <origin xyz="0 0 0" rpy="0 0 0" />
        <mass value="0.038484" />
        <inertia
          ixx="0.0" ixy="0.0" ixz="0.0"
          iyy="0.0" iyz="0.0"
          izz="0.0" />
    
    </inertial>
    </link>
    <joint name="RX90_RGRIPPER_JOINT" type="prismatic">
    <limit effort="100000.0" lower="-100000" upper="1" velocity="20"/>
       <parent link="RX90_FLANGE" />
       <child link="RX90_RGRIPPER" />
       <origin rpy="0 0 ${-pi/2}" xyz="0.025 -0.03 0.015" />
    </joint>


     <link name="RX90_MGRIPPER">
       <visual>
	<origin rpy="0 0 0" xyz="0 0 0" />
          <geometry>
            <box size="0.02 0.045 0.01"/>
          </geometry>
       </visual>
	<collision>
        <origin rpy="0 0 0" xyz="0 0 0" />
            <geometry>
              <box size="0.02 0.045 0.01"/>
            </geometry>
       </collision>
       <selfCollide>true</selfCollide>
	<inertial>
       <origin xyz="0 0 0" rpy="0 0 0" />
        <mass value="0.038484" />
        <inertia
          ixx="0.0" ixy="0.0" ixz="0.0"
          iyy="0.0" iyz="0.0"
          izz="0.0" />
    
    </inertial>
    </link>
    <joint name="RX90_MGRIPPER_JOINT" type="prismatic">
    <limit effort="100000.0" lower="-100000" upper="1" velocity="20"/>
       <parent link="RX90_FLANGE" />
       <child link="RX90_MGRIPPER" />
       <origin rpy="0 ${pi/2} ${-pi/2}" xyz="0.025 0 -0.035" />
    </joint>
 


 
</robot>
